ERROR - 2022-10-16 21:54:42 --> Error connecting to the database: Unknown database 'project_db'
CRITICAL - 2022-10-16 21:54:42 --> Unable to connect to the database.
Main connection [MySQLi]: Unknown database 'project_db'
#0 C:\xampp\htdocs\codeigniter4\vendor\codeigniter4\framework\system\Database\BaseConnection.php(577): CodeIgniter\Database\BaseConnection->initialize()
#1 C:\xampp\htdocs\codeigniter4\app\Models\Auth_Model.php(87): CodeIgniter\Database\BaseConnection->query('Select * FROM c...')
#2 C:\xampp\htdocs\codeigniter4\app\Controllers\Auth.php(44): App\Models\Auth_Model->validate_auth_model('admin', 'eb184cc3e446972...')
#3 C:\xampp\htdocs\codeigniter4\vendor\codeigniter4\framework\system\CodeIgniter.php(832): App\Controllers\Auth->validate_login()
#4 C:\xampp\htdocs\codeigniter4\vendor\codeigniter4\framework\system\CodeIgniter.php(419): CodeIgniter\CodeIgniter->runController(Object(App\Controllers\Auth))
#5 C:\xampp\htdocs\codeigniter4\vendor\codeigniter4\framework\system\CodeIgniter.php(326): CodeIgniter\CodeIgniter->handleRequest(NULL, Object(Config\Cache), false)
#6 C:\xampp\htdocs\codeigniter4\index.php(37): CodeIgniter\CodeIgniter->run()
#7 {main}
CRITICAL - 2022-10-16 21:54:42 --> Uncaught ErrorException: print_r(): Property access is not allowed yet in C:\xampp\htdocs\codeigniter4\app\Views\errors\html\error_exception.php:96
Stack trace:
#0 [internal function]: CodeIgniter\Debug\Exceptions->errorHandler(2, 'print_r(): Prop...', 'C:\\xampp\\htdocs...', 96, Array)
#1 C:\xampp\htdocs\codeigniter4\app\Views\errors\html\error_exception.php(96): print_r(Object(App\Controllers\Auth), true)
#2 C:\xampp\htdocs\codeigniter4\vendor\codeigniter4\framework\system\Debug\Exceptions.php(234): include('C:\\xampp\\htdocs...')
#3 C:\xampp\htdocs\codeigniter4\vendor\codeigniter4\framework\system\Debug\Exceptions.php(237): CodeIgniter\Debug\Exceptions->CodeIgniter\Debug\{closure}()
#4 C:\xampp\htdocs\codeigniter4\vendor\codeigniter4\framework\system\Debug\Exceptions.php(121): CodeIgniter\Debug\Exceptions->render(Object(CodeIgniter\Database\Exceptions\DatabaseException), 500)
#5 [internal function]: CodeIgniter\Debug\Exceptions->exceptionHandler(Object(CodeIgniter\Database\Exceptions\DatabaseException))
#6
#0 [internal function]: CodeIgniter\Debug\Exceptions->shutdownHandler()
#1 {main}
ERROR - 2022-10-16 22:02:39 --> Error connecting to the database: Unknown database 'project_db'
CRITICAL - 2022-10-16 22:02:39 --> Unable to connect to the database.
Main connection [MySQLi]: Unknown database 'project_db'
#0 C:\xampp\htdocs\codeigniter4\vendor\codeigniter4\framework\system\Database\BaseConnection.php(577): CodeIgniter\Database\BaseConnection->initialize()
#1 C:\xampp\htdocs\codeigniter4\app\Models\Auth_Model.php(87): CodeIgniter\Database\BaseConnection->query('Select * FROM c...')
#2 C:\xampp\htdocs\codeigniter4\app\Controllers\Auth.php(44): App\Models\Auth_Model->validate_auth_model('admin', 'eb184cc3e446972...')
#3 C:\xampp\htdocs\codeigniter4\vendor\codeigniter4\framework\system\CodeIgniter.php(832): App\Controllers\Auth->validate_login()
#4 C:\xampp\htdocs\codeigniter4\vendor\codeigniter4\framework\system\CodeIgniter.php(419): CodeIgniter\CodeIgniter->runController(Object(App\Controllers\Auth))
#5 C:\xampp\htdocs\codeigniter4\vendor\codeigniter4\framework\system\CodeIgniter.php(326): CodeIgniter\CodeIgniter->handleRequest(NULL, Object(Config\Cache), false)
#6 C:\xampp\htdocs\codeigniter4\index.php(37): CodeIgniter\CodeIgniter->run()
#7 {main}
CRITICAL - 2022-10-16 22:02:39 --> Uncaught ErrorException: print_r(): Property access is not allowed yet in C:\xampp\htdocs\codeigniter4\app\Views\errors\html\error_exception.php:96
Stack trace:
#0 [internal function]: CodeIgniter\Debug\Exceptions->errorHandler(2, 'print_r(): Prop...', 'C:\\xampp\\htdocs...', 96, Array)
#1 C:\xampp\htdocs\codeigniter4\app\Views\errors\html\error_exception.php(96): print_r(Object(App\Controllers\Auth), true)
#2 C:\xampp\htdocs\codeigniter4\vendor\codeigniter4\framework\system\Debug\Exceptions.php(234): include('C:\\xampp\\htdocs...')
#3 C:\xampp\htdocs\codeigniter4\vendor\codeigniter4\framework\system\Debug\Exceptions.php(237): CodeIgniter\Debug\Exceptions->CodeIgniter\Debug\{closure}()
#4 C:\xampp\htdocs\codeigniter4\vendor\codeigniter4\framework\system\Debug\Exceptions.php(121): CodeIgniter\Debug\Exceptions->render(Object(CodeIgniter\Database\Exceptions\DatabaseException), 500)
#5 [internal function]: CodeIgniter\Debug\Exceptions->exceptionHandler(Object(CodeIgniter\Database\Exceptions\DatabaseException))
#6
#0 [internal function]: CodeIgniter\Debug\Exceptions->shutdownHandler()
#1 {main}
ERROR - 2022-10-16 22:03:11 --> Error connecting to the database: Unknown database 'project_db'
CRITICAL - 2022-10-16 22:03:11 --> Unable to connect to the database.
Main connection [MySQLi]: Unknown database 'project_db'
#0 C:\xampp\htdocs\codeigniter4\vendor\codeigniter4\framework\system\Database\BaseConnection.php(577): CodeIgniter\Database\BaseConnection->initialize()
#1 C:\xampp\htdocs\codeigniter4\app\Models\Auth_Model.php(87): CodeIgniter\Database\BaseConnection->query('Select * FROM c...')
#2 C:\xampp\htdocs\codeigniter4\app\Controllers\Auth.php(44): App\Models\Auth_Model->validate_auth_model('admin', '21232f297a57a5a...')
#3 C:\xampp\htdocs\codeigniter4\vendor\codeigniter4\framework\system\CodeIgniter.php(832): App\Controllers\Auth->validate_login()
#4 C:\xampp\htdocs\codeigniter4\vendor\codeigniter4\framework\system\CodeIgniter.php(419): CodeIgniter\CodeIgniter->runController(Object(App\Controllers\Auth))
#5 C:\xampp\htdocs\codeigniter4\vendor\codeigniter4\framework\system\CodeIgniter.php(326): CodeIgniter\CodeIgniter->handleRequest(NULL, Object(Config\Cache), false)
#6 C:\xampp\htdocs\codeigniter4\index.php(37): CodeIgniter\CodeIgniter->run()
#7 {main}
CRITICAL - 2022-10-16 22:03:11 --> Uncaught ErrorException: print_r(): Property access is not allowed yet in C:\xampp\htdocs\codeigniter4\app\Views\errors\html\error_exception.php:96
Stack trace:
#0 [internal function]: CodeIgniter\Debug\Exceptions->errorHandler(2, 'print_r(): Prop...', 'C:\\xampp\\htdocs...', 96, Array)
#1 C:\xampp\htdocs\codeigniter4\app\Views\errors\html\error_exception.php(96): print_r(Object(App\Controllers\Auth), true)
#2 C:\xampp\htdocs\codeigniter4\vendor\codeigniter4\framework\system\Debug\Exceptions.php(234): include('C:\\xampp\\htdocs...')
#3 C:\xampp\htdocs\codeigniter4\vendor\codeigniter4\framework\system\Debug\Exceptions.php(237): CodeIgniter\Debug\Exceptions->CodeIgniter\Debug\{closure}()
#4 C:\xampp\htdocs\codeigniter4\vendor\codeigniter4\framework\system\Debug\Exceptions.php(121): CodeIgniter\Debug\Exceptions->render(Object(CodeIgniter\Database\Exceptions\DatabaseException), 500)
#5 [internal function]: CodeIgniter\Debug\Exceptions->exceptionHandler(Object(CodeIgniter\Database\Exceptions\DatabaseException))
#6
#0 [internal function]: CodeIgniter\Debug\Exceptions->shutdownHandler()
#1 {main}
ERROR - 2022-10-16 22:17:52 --> Error connecting to the database: No connection could be made because the target machine actively refused it.

CRITICAL - 2022-10-16 22:17:52 --> Unable to connect to the database.
Main connection [MySQLi]: No connection could be made because the target machine actively refused it.

#0 C:\xampp\htdocs\codeigniter4\vendor\codeigniter4\framework\system\Database\BaseConnection.php(577): CodeIgniter\Database\BaseConnection->initialize()
#1 C:\xampp\htdocs\codeigniter4\app\Models\Auth_Model.php(87): CodeIgniter\Database\BaseConnection->query('Select * FROM c...')
#2 C:\xampp\htdocs\codeigniter4\app\Controllers\Auth.php(44): App\Models\Auth_Model->validate_auth_model('admin', '21232f297a57a5a...')
#3 C:\xampp\htdocs\codeigniter4\vendor\codeigniter4\framework\system\CodeIgniter.php(832): App\Controllers\Auth->validate_login()
#4 C:\xampp\htdocs\codeigniter4\vendor\codeigniter4\framework\system\CodeIgniter.php(419): CodeIgniter\CodeIgniter->runController(Object(App\Controllers\Auth))
#5 C:\xampp\htdocs\codeigniter4\vendor\codeigniter4\framework\system\CodeIgniter.php(326): CodeIgniter\CodeIgniter->handleRequest(NULL, Object(Config\Cache), false)
#6 C:\xampp\htdocs\codeigniter4\index.php(37): CodeIgniter\CodeIgniter->run()
#7 {main}
CRITICAL - 2022-10-16 22:17:52 --> Uncaught ErrorException: print_r(): Property access is not allowed yet in C:\xampp\htdocs\codeigniter4\app\Views\errors\html\error_exception.php:96
Stack trace:
#0 [internal function]: CodeIgniter\Debug\Exceptions->errorHandler(2, 'print_r(): Prop...', 'C:\\xampp\\htdocs...', 96, Array)
#1 C:\xampp\htdocs\codeigniter4\app\Views\errors\html\error_exception.php(96): print_r(Object(App\Controllers\Auth), true)
#2 C:\xampp\htdocs\codeigniter4\vendor\codeigniter4\framework\system\Debug\Exceptions.php(234): include('C:\\xampp\\htdocs...')
#3 C:\xampp\htdocs\codeigniter4\vendor\codeigniter4\framework\system\Debug\Exceptions.php(237): CodeIgniter\Debug\Exceptions->CodeIgniter\Debug\{closure}()
#4 C:\xampp\htdocs\codeigniter4\vendor\codeigniter4\framework\system\Debug\Exceptions.php(121): CodeIgniter\Debug\Exceptions->render(Object(CodeIgniter\Database\Exceptions\DatabaseException), 500)
#5 [internal function]: CodeIgniter\Debug\Exceptions->exceptionHandler(Object(CodeIgniter\Database\Exceptions\DatabaseException))
#6
#0 [internal function]: CodeIgniter\Debug\Exceptions->shutdownHandler()
#1 {main}
ERROR - 2022-10-16 22:18:01 --> Error connecting to the database: No connection could be made because the target machine actively refused it.

CRITICAL - 2022-10-16 22:18:01 --> Unable to connect to the database.
Main connection [MySQLi]: No connection could be made because the target machine actively refused it.

#0 C:\xampp\htdocs\codeigniter4\vendor\codeigniter4\framework\system\Database\BaseConnection.php(577): CodeIgniter\Database\BaseConnection->initialize()
#1 C:\xampp\htdocs\codeigniter4\app\Models\Auth_Model.php(87): CodeIgniter\Database\BaseConnection->query('Select * FROM c...')
#2 C:\xampp\htdocs\codeigniter4\app\Controllers\Auth.php(44): App\Models\Auth_Model->validate_auth_model('admin', '21232f297a57a5a...')
#3 C:\xampp\htdocs\codeigniter4\vendor\codeigniter4\framework\system\CodeIgniter.php(832): App\Controllers\Auth->validate_login()
#4 C:\xampp\htdocs\codeigniter4\vendor\codeigniter4\framework\system\CodeIgniter.php(419): CodeIgniter\CodeIgniter->runController(Object(App\Controllers\Auth))
#5 C:\xampp\htdocs\codeigniter4\vendor\codeigniter4\framework\system\CodeIgniter.php(326): CodeIgniter\CodeIgniter->handleRequest(NULL, Object(Config\Cache), false)
#6 C:\xampp\htdocs\codeigniter4\index.php(37): CodeIgniter\CodeIgniter->run()
#7 {main}
CRITICAL - 2022-10-16 22:18:01 --> Uncaught ErrorException: print_r(): Property access is not allowed yet in C:\xampp\htdocs\codeigniter4\app\Views\errors\html\error_exception.php:96
Stack trace:
#0 [internal function]: CodeIgniter\Debug\Exceptions->errorHandler(2, 'print_r(): Prop...', 'C:\\xampp\\htdocs...', 96, Array)
#1 C:\xampp\htdocs\codeigniter4\app\Views\errors\html\error_exception.php(96): print_r(Object(App\Controllers\Auth), true)
#2 C:\xampp\htdocs\codeigniter4\vendor\codeigniter4\framework\system\Debug\Exceptions.php(234): include('C:\\xampp\\htdocs...')
#3 C:\xampp\htdocs\codeigniter4\vendor\codeigniter4\framework\system\Debug\Exceptions.php(237): CodeIgniter\Debug\Exceptions->CodeIgniter\Debug\{closure}()
#4 C:\xampp\htdocs\codeigniter4\vendor\codeigniter4\framework\system\Debug\Exceptions.php(121): CodeIgniter\Debug\Exceptions->render(Object(CodeIgniter\Database\Exceptions\DatabaseException), 500)
#5 [internal function]: CodeIgniter\Debug\Exceptions->exceptionHandler(Object(CodeIgniter\Database\Exceptions\DatabaseException))
#6
#0 [internal function]: CodeIgniter\Debug\Exceptions->shutdownHandler()
#1 {main}
ERROR - 2022-10-16 22:43:02 --> Error connecting to the database: No connection could be made because the target machine actively refused it.

CRITICAL - 2022-10-16 22:43:02 --> Unable to connect to the database.
Main connection [MySQLi]: No connection could be made because the target machine actively refused it.

#0 C:\xampp\htdocs\codeigniter4\vendor\codeigniter4\framework\system\Database\BaseConnection.php(577): CodeIgniter\Database\BaseConnection->initialize()
#1 C:\xampp\htdocs\codeigniter4\app\Models\Auth_Model.php(87): CodeIgniter\Database\BaseConnection->query('Select * FROM c...')
#2 C:\xampp\htdocs\codeigniter4\app\Controllers\Auth.php(44): App\Models\Auth_Model->validate_auth_model('admin', '21232f297a57a5a...')
#3 C:\xampp\htdocs\codeigniter4\vendor\codeigniter4\framework\system\CodeIgniter.php(832): App\Controllers\Auth->validate_login()
#4 C:\xampp\htdocs\codeigniter4\vendor\codeigniter4\framework\system\CodeIgniter.php(419): CodeIgniter\CodeIgniter->runController(Object(App\Controllers\Auth))
#5 C:\xampp\htdocs\codeigniter4\vendor\codeigniter4\framework\system\CodeIgniter.php(326): CodeIgniter\CodeIgniter->handleRequest(NULL, Object(Config\Cache), false)
#6 C:\xampp\htdocs\codeigniter4\index.php(37): CodeIgniter\CodeIgniter->run()
#7 {main}
CRITICAL - 2022-10-16 22:43:02 --> Uncaught ErrorException: print_r(): Property access is not allowed yet in C:\xampp\htdocs\codeigniter4\app\Views\errors\html\error_exception.php:96
Stack trace:
#0 [internal function]: CodeIgniter\Debug\Exceptions->errorHandler(2, 'print_r(): Prop...', 'C:\\xampp\\htdocs...', 96, Array)
#1 C:\xampp\htdocs\codeigniter4\app\Views\errors\html\error_exception.php(96): print_r(Object(App\Controllers\Auth), true)
#2 C:\xampp\htdocs\codeigniter4\vendor\codeigniter4\framework\system\Debug\Exceptions.php(234): include('C:\\xampp\\htdocs...')
#3 C:\xampp\htdocs\codeigniter4\vendor\codeigniter4\framework\system\Debug\Exceptions.php(237): CodeIgniter\Debug\Exceptions->CodeIgniter\Debug\{closure}()
#4 C:\xampp\htdocs\codeigniter4\vendor\codeigniter4\framework\system\Debug\Exceptions.php(121): CodeIgniter\Debug\Exceptions->render(Object(CodeIgniter\Database\Exceptions\DatabaseException), 500)
#5 [internal function]: CodeIgniter\Debug\Exceptions->exceptionHandler(Object(CodeIgniter\Database\Exceptions\DatabaseException))
#6
#0 [internal function]: CodeIgniter\Debug\Exceptions->shutdownHandler()
#1 {main}
ERROR - 2022-10-16 23:20:43 --> Error connecting to the database: No connection could be made because the target machine actively refused it.

CRITICAL - 2022-10-16 23:20:43 --> Unable to connect to the database.
Main connection [MySQLi]: No connection could be made because the target machine actively refused it.

#0 C:\xampp\htdocs\codeigniter4\vendor\codeigniter4\framework\system\Database\BaseConnection.php(577): CodeIgniter\Database\BaseConnection->initialize()
#1 C:\xampp\htdocs\codeigniter4\app\Models\Auth_Model.php(87): CodeIgniter\Database\BaseConnection->query('Select * FROM c...')
#2 C:\xampp\htdocs\codeigniter4\app\Controllers\Auth.php(44): App\Models\Auth_Model->validate_auth_model('admin', '21232f297a57a5a...')
#3 C:\xampp\htdocs\codeigniter4\vendor\codeigniter4\framework\system\CodeIgniter.php(832): App\Controllers\Auth->validate_login()
#4 C:\xampp\htdocs\codeigniter4\vendor\codeigniter4\framework\system\CodeIgniter.php(419): CodeIgniter\CodeIgniter->runController(Object(App\Controllers\Auth))
#5 C:\xampp\htdocs\codeigniter4\vendor\codeigniter4\framework\system\CodeIgniter.php(326): CodeIgniter\CodeIgniter->handleRequest(NULL, Object(Config\Cache), false)
#6 C:\xampp\htdocs\codeigniter4\index.php(37): CodeIgniter\CodeIgniter->run()
#7 {main}
CRITICAL - 2022-10-16 23:20:43 --> Uncaught ErrorException: print_r(): Property access is not allowed yet in C:\xampp\htdocs\codeigniter4\app\Views\errors\html\error_exception.php:96
Stack trace:
#0 [internal function]: CodeIgniter\Debug\Exceptions->errorHandler(2, 'print_r(): Prop...', 'C:\\xampp\\htdocs...', 96, Array)
#1 C:\xampp\htdocs\codeigniter4\app\Views\errors\html\error_exception.php(96): print_r(Object(App\Controllers\Auth), true)
#2 C:\xampp\htdocs\codeigniter4\vendor\codeigniter4\framework\system\Debug\Exceptions.php(234): include('C:\\xampp\\htdocs...')
#3 C:\xampp\htdocs\codeigniter4\vendor\codeigniter4\framework\system\Debug\Exceptions.php(237): CodeIgniter\Debug\Exceptions->CodeIgniter\Debug\{closure}()
#4 C:\xampp\htdocs\codeigniter4\vendor\codeigniter4\framework\system\Debug\Exceptions.php(121): CodeIgniter\Debug\Exceptions->render(Object(CodeIgniter\Database\Exceptions\DatabaseException), 500)
#5 [internal function]: CodeIgniter\Debug\Exceptions->exceptionHandler(Object(CodeIgniter\Database\Exceptions\DatabaseException))
#6
#0 [internal function]: CodeIgniter\Debug\Exceptions->shutdownHandler()
#1 {main}
